<robot name="two_wheeled_robot">
  <!-- Main Body -->
  <link name="body">
    <inertial>
      <origin xyz="0 0 0.25" rpy="0 0 0"/>
      <mass value="10"/>
      <inertia ixx="0.01" ixy="0" ixz="0" iyy="0.01" iyz="0" izz="0.02"/>
    </inertial>
    <visual>
      <origin xyz="0 0 0.25" rpy="0 0 0"/>
      <geometry>
        <box size="1 0.5 0.3"/>
      </geometry>
      <material name="orange">
        <color rgba="1 0.647 0 1"/>
      </material>
    </visual>
    <collision>
      <origin xyz="0 0 0.25" rpy="0 0 0"/>
      <geometry>
        <box size="1 0.5 0.3"/>
      </geometry>
    </collision>
  </link>

  <!-- Left Wheel -->
  <link name="left_wheel">
    <inertial>
      <origin xyz="0 0 0" rpy="0 0 0"/>
      <mass value="1.0"/>
      <inertia ixx="0.005" ixy="0" ixz="0" iyy="0.005" iyz="0" izz="0.01"/>
    </inertial>
    <visual>
      <origin xyz="0 0 0" rpy="0 0 0"/>
      <geometry>
        <cylinder radius="0.1" length="0.05"/>
      </geometry>
      <material name="black"/>
    </visual>

  </link>

  <!-- Right Wheel -->
  <link name="right_wheel">
    <inertial>
      <origin xyz="0 0 0" rpy="0 0 0"/>
      <mass value="1.0"/>
      <inertia ixx="0.005" ixy="0" ixz="0" iyy="0.005" iyz="0" izz="0.01"/>
    </inertial>
    <visual>
      <origin xyz="0 0 0" rpy="0 0 0"/>
      <geometry>
        <cylinder radius="0.1" length="0.05"/>
      </geometry>
      <material name="black"/>
    </visual>

  </link>

  <!-- Joints -->
  <joint name="left_wheel_joint" type="continuous">
    <parent link="body"/>
    <child link="left_wheel"/>
    <origin xyz="0.6 -0.2 0.4" rpy="-1.5 0 0"/>
    <axis xyz="0 1 0"/>
  </joint>

  <joint name="right_wheel_joint" type="continuous">
    <parent link="body"/>
    <child link="right_wheel"/>
    <origin xyz="0.6 0.2 0.4" rpy="-1.5 0 0"/>
    <axis xyz="0 1 0"/>
  </joint>
  
</robot>
